Workbook

Sheet Summary
B2: MSC
A5: ATTENDANCE
A6: APOINTED SERVICE | B6: ROB + Sludge Disposal
A7: VESSEL | B7: MSC SABRINA
A8: VOY | B8: MM623R
A9: GRADE 1 | B9: R HS | C9: NO
A10: GRADE 2 | B10: R VLS | C10: YES
A11: GRADE 3 | B11: DISTILLATES | C11: YES
A12: GRADE 4 | B12: LNG | C12: NO
A13: TERMINAL | B13: TERMINAL DE CONTAINER DE PARANAGUA
A14: PORT | B14: PARANAGUA
A15: SURVEYORS | B15: ARMANDO JUNIOR
A16: LAST ATTENDANCE | B16: No
A17: BERTHING MESSAGE
A18: DATE | B18: 46249
A19: TIME | B19: 0.83333333
A20: VESSEL DETAILS
A21: IMO | B21: 9979022
A22: FLAG | B22: Liberia
A23: PORTO OF REGISTER | B23: MONROVIA
A24: GRT | B24: 101.311
A25: NET | B25: 63.767
A26: DELIVERED | B26: 2026
A27: OWNER | B27: FULANO DE TAL
A28: MANAGER | B28: MSC SHIPMANAGEMENT LIMITED, LIMASSOL, CYPRUS
A29: CALL SIGN | B29: A8CA7
A30: TYPE | B30: Container Carrier
A31: LOA (m) | B31: 335
A32: LBP (m) | B32: 329.5
A33: BREADTH (m) | B33: 45.6
A34: DEPTH (m) | B34: 25.4
A35: LIGHT SHIP (t) | B35: 37922.27
A36: VESSEL´S COMMAND
A37: CAPITAIN | B37: MUKESH MAHENDRA MIRANDA
A38: CHIEF ENGINEER | B38: SIBI JESU ANTHONY
A39: QUEM SONDOU

Sheet Time Log
B2: TIME LOG AND CHECK LIST
F4: Date | G4: Time
B5: Surveyor arrived at terminal | F5: 46188 | G5: 0.41666667 | H5: x
B6: Surveyor authorized by Terminal to board vessel | F6: 46188 | G6: 0.45833333 | H6: x
B7: Surveyor on board | F7: 46188 | G7: 0.5 | H7: x
B8: Key meeting | F8: 46188 | G8: 0.5 | H8: x | I8: 0.50694444
B9: Opening soundings | F9: 46188 | G9: 0.50694444 | H9: x | I9: 0.54166667
B10: Trucks arrived | F10: 46188 | G10: 0.49305556 | H10: x
B11: Hose conected | F11: 46188 | G11: 0.52083333 | H11: x
B12: Pumping operation | F12: 46188 | G12: 0.54166667 | H12: x | I12: 0.91666667
B13: Closing soundings | F13: 46188 | G13: 0.91666667 | H13: x | I13: 0.95833333
B14: Calculation | F14: 46189 | G14: 0 | H14: x | I14: 0.041666667
B15: Documents signed | F15: 46189 | G15: 0.048611111 | H15: x
B16: Surveyor left board | F16: 46189 | G16: 0.052083333 | H16: x
B19: DOCUMENTS | K19: Check List
B20: Ship´s Particulars
B21: Crew list
B22: BDN - Bunker Delivered Notice (If bunkering between last disposal and the actual)
B23: Berthing message (VRS with ROB Bunker and Sludge)
B24: Last manual sounding | L24: Date: | N24: Attached:
B25: Sludge message (Sent after disposal – Quantity landed/retained on board)
B26: Copy of Oil Record Book (pages with last disposal and at berthing)
B27: Copy of last Survey Report performed
B28: Copy of last flowmeter calibration certificate | F28: (ME) | L28: Date:
B29: Copy of last flowmeter calibration certificate | F29: (AE) | L29: Date:
B30: Copy of last flowmeter calibration certificate | F30: (BOILER) | L30: Date:
B31: Copy of last manual sounding
B32: VRS | D32: Version | F32: Updated
B33: Logbook Updated | D33: Attached
B35: TEMPERATURES
B36: FO Storage tanks | C36: Display at ECR
B37: FO Serv & Sett | C37: Glass thermometer
B38: DO tanks | C38: ER
B39: Engine Room | C39: 30 | D39: °C
B40: Sea Water | C40: 21 | D40: °C
B42: Observações (Onde foram verificadas as temperaturas, se houve alguma intercorrência, etc)

Sheet Qtt Sumary
A4: Name of Vessel | C4: =Summary!B7 -> MSC SABRINA | E4: IMO | F4: =Summary!B21 -> 9979022 | H4: VOY | I4: =Summary!B8 -> MM623R
A5: Location of Survey | C5: =Summary!B13 -> TERMINAL DE CONTAINER DE PARANAGUA | E5: Started | F5: ='Time Log'!F7 -> 46188 | G5: ='Time Log'!G7 -> 0.5 | I5: h
A6: Port | C6: =Summary!B14 -> PARANAGUA | E6: Completed | F6: ='Time Log'!F14 -> 46189 | G6: ='Time Log'!I14 -> 0.041666667 | I6: h
A8: QUANTITIES SUMMARY
A10: DESCRIPTION | E10: GRADE | F10: QUANTITY
A11: Actual quantity as per surveyor | E11: =Summary!B9 -> R HS | F11: ='Vessel Ullage'!N43 -> 114.78 | H11: MT
A12: Berthing Report | E12: =E11 -> R HS | F12: ='Vessel Ullage'!K48 -> 151 | H12: MT
A13: Difference | E13: =E11 -> R HS | F13: =F11-F12 -> -36.22 | H13: MT
A14: Percentage | E14: =E11 -> R HS | F14: =IFERROR(F13/F12*100,0) -> -23.986755 | H14: %
A16: Actual quantity as per surveyor | E16: =Summary!B10 -> R VLS | F16: ='Vessel Ullage'!N44 -> 581.68 | H16: MT
A17: Berthing Report | E17: =E16 -> R VLS | F17: ='Vessel Ullage'!K49 -> 161 | H17: MT
A18: Difference | E18: =E16 -> R VLS | F18: =F16-F17 -> 420.68 | H18: MT
A19: Percentage | E19: =E16 -> R VLS | F19: =IFERROR(F18/F17*100,0) -> 261.29193 | H19: %
A21: Actual quantity as per surveyor | E21: =Summary!B11 -> DISTILLATES | F21: ='Vessel Ullage'!N45 -> 3.5045 | H21: MT
A22: Berthing Report | E22: =E21 -> DISTILLATES | F22: ='Vessel Ullage'!K50 -> 171 | H22: MT
A23: Difference | E23: =E21 -> DISTILLATES | F23: =F21-F22 -> -167.4955 | H23: MT
A24: Percentage | E24: =E21 -> DISTILLATES | F24: =IFERROR(F23/F22*100,0) -> -97.950585 | H24: %
A26: Actual quantity as per surveyor | E26: =Summary!B12 -> LNG | F26: =LNG!C39 -> 2285.627 | H26: MT
A27: Berthing Report | E27: LNG | F27: =LNG!J47 -> 2317.25 | H27: MT
A28: Difference | E28: LNG | F28: =F26-F27 -> -31.623 | H28: MT
A29: Percentage | E29: =E26 -> LNG | F29: =IFERROR(F28/F27*100,0) -> -1.364678 | H29: %
A31: Actual quantity as per surveyor | E31: SLUDGE | F31: =Sludge!E24 -> 72.57 | H31: m3
A32: Berthing Report | E32: SLUDGE | F32: =Sludge!D30 -> 63.7 | H32: m3
A33: Difference | E33: SLUDGE | F33: =F31-F32 -> 8.87 | H33: m3
A34: Percentage | E34: SLUDGE | F34: =(F33/F32)*100 -> 13.924647 | H34: %
A35: Last sludge discharge (date) | E35: SLUDGE | F35: =Sludge!D27 -> 46157
A36: Last sludge discharge quantity | E36: SLUDGE | F36: =Sludge!D28 -> 50 | H36: m3
A37: Sludge retained after last discharge | E37: SLUDGE | F37: =Sludge!D29 -> 10 | H37: m3
A38: Sludge generated from last discharge | E38: SLUDGE | F38: =Sludge!D31 -> 53.7 | H38: m3
A39: IFO consumption since last sludge discharged | E39: SLUDGE | F39: ='LOG Audit'!H16 -> 180 | H39: MT
A40: Sludge generated percentage (including water) | E40: SLUDGE | F40: =IFERROR((F38/F39)*100,0) -> 29.833333 | H40: %
A41: Sludge discharged at Paranagua Port | E41: SLUDGE | F41: =Sludge!K24 -> 47.02 | H41: m3
A42: ROB of sludge after discharged | E42: SLUDGE | F42: =Sludge!D34 -> 16.68 | H42: m3
A43: Water in Sludge percentage | E43: SLUDGE | F43: NI | H43: %
A54: CHIEF ENGINEER: | C54: =Summary!B38 -> SIBI JESU ANTHONY | F54: SURVEYOR: | G54: =Summary!B15 -> ARMANDO JUNIOR

Sheet Sludge
B3: Name of Vessel | C3: =Summary!B7 -> MSC SABRINA | H3: IMO | I3: =Summary!B21 -> 9979022 | J3: VOY | K3: =Summary!B8 -> MM623R
B4: Location of Survey | C4: =Summary!B13 -> TERMINAL DE CONTAINER DE PARANAGUA | H4: Started | I4: ='Time Log'!F7 -> 46188 | J4: ='Time Log'!G7 -> 0.5 | K4: h
B5: Port | C5: =Summary!B14 -> PARANAGUA | H5: Completed | I5: ='Time Log'!F14 -> 46189 | J5: ='Time Log'!I14 -> 0.041666667 | K5: h
B7: SLUDGE SUMMARY
B9: MISCELLANEOUS
B10: Tank | C10: Before Disposal | H10: After Disposal
C11: Sounding | E11: m3 | H11: Sounding | I11: m3
B12: BILGE HT | C12: 1.15 | E12: 54.25 | H12: 1.15 | I12: 54.25 | K12: =E12+E13 -> 54.25 | L12: =K12-K13 -> 0
K13: =I12+I13 -> 54.25
B15: SLUDGE TANKS - SURVEYOR
B16: Tank | C16: Before Disposal | H16: After Disposal
C17: Sounding | E17: m3 | H17: Sounding | I17: m3
B18: SLUDGE TK | C18: 1.93 | E18: 46.7 | H18: 1.09 | I18: 18.185
B19: FO PURIFIRER | C19: 0.84 | E19: 15.12 | H19: 0.19 | I19: 2.565
B20: LO PURIFIRER | C20: 0.61 | E20: 8.3 | H20: 0.17 | I20: 2.35
B21: FO DRAIN | C21: 0.14 | E21: 2.01 | H21: 0.14 | I21: 2.01
B22: LO DRAIN | C22: 0 | E22: 0.44 | H22: 0 | I22: 0.44
B23: WO SERVICE 1 | C23: GAUGE | E23: 0 | H23: GAUGE | I23: 0 | K23: Disposed
B24: TOTAL | E24: =SUM(E18:E23) -> 72.57 | H24: TOTAL | I24: =SUM(I18:J23) -> 25.55 | K24: =E24-I24 -> 47.02 | L24: m³
B26: VESSEL´S RECORDS
B27: Sludge - Last Disposal Date | D27: 46157
B28: Sludge - Last Disposal | D28: 50 | F28: m³ | H28: PURIFIERS SETTINGS
B29: Sludge Retained Aft Last Disposal | D29: 10 | F29: m³ | H29: Temperature (°C) | K29: 98
B30: Sludge at berthing - Berthing Report | D30: 63.7 | F30: m³ | H30: Flow setting by each purifier (1 x 1,1m3) | K30: 1 x 2,0
B31: Sludge Production | D31: =D30-D29 -> 53.7 | F31: m³ | H31: Bowl disch freq. in minutes (60;120) | K31: 60
B32: Log book Consumption | D32: ='LOG Audit'!H16 -> 180 | F32: mt
B33: Sludge Rate Production | D33: =IFERROR((D31/D32)*100,0) -> 29.833333 | F33: %
B34: Sludge retained aft actual disposal | D34: =D30-K24 -> 16.68 | F34: m³
B36: SURVEYOR FIGURES
B37: Sludge ROB at berthing | D37: =E24 -> 72.57 | F37: m³
B38: Sludge Production | D38: =D37-D29 -> 62.57 | F38: m³
B39: Log book Consumption | D39: =('LOG Audit'!C16+'LOG Audit'!D16)-'Vessel Ullage'!L51 -> -189.9645 | F39: mt
B40: Difference btw logbook and FLM | D40: =D39-'LOG Audit'!E37 -> -3115.36 | F40: mt | G40: =(D40/'LOG Audit'!E37)*100 -> -106.49363
B41: Sludge Rate Production | D41: =IFERROR((D38/D39)*100,0) -> -32.937733 | F41: %
B42: Sludge retained | D42: =D37-K24 -> 25.55 | F42: m³
B44: TRUCK DETAILS | F44: m³
B45: 1st truck | C45: Start | D45: 0.98125 | E45: =D46-D45 -> 0.041666667 | F45: 15
B46: RFC 2E94 | C46: Finish | D46: 1.0229167
B47: 2nd truck | C47: Start | D47: 0.41666667 | E47: =D48-D47 -> 0.041666667 | F47: 15
C48: Finish | D48: 0.45833333
...

Sheet Vessel Ullage
B4: Name of Vessel | D4: =Summary!B7 -> MSC SABRINA | H4: IMO | J4: =Summary!B21 -> 9979022 | K4: VOY | L4: =Summary!B8 -> MM623R
B5: Location of Survey | D5: =Summary!B13 -> TERMINAL DE CONTAINER DE PARANAGUA | H5: Started | J5: ='Time Log'!F7 -> 46188 | L5: ='Time Log'!G7 -> 0.5
B6: Port | D6: =Summary!B14 -> PARANAGUA | H6: Completed | J6: ='Time Log'!F14 -> 46189 | L6: ='Time Log'!I14 -> 0.041666667
B8: VESSEL´S SOUNDING/ULLAGE REPORT
B10: BEFORE DISPOSAL
B11: Draft Fore: | C11: 9.45 | D11: m | E11: Draft Aft: | F11: 10.5 | G11: m | H11: List: | I11: NA | J11: Trim Correction Applied: | L11: Yes | M11: Metric Tons | U11: =F11-C11 -> 1.05
B12: Tank Nº | C12: Grade | D12: Mtrs Sounding or Ullage | E12: Deg ºc | F12: Total Obs Vol (m3) | G12: Free Water | I12: Gross Obs Vol (m3) | J12: VCF TABLE 54B | K12: Density at 15deg | L12: Gross Std Vol at 15Deg | M12: In Vac | N12: In Air
G13: Dip | H13: Vol
B15: HFO 1P | C15: R HS | D15: 1 | E15: 15 | F15: 10 | G15: Nil | H15: 0 | I15: =IF(F15="","",F15-H15) -> 10 | J15: =IF(F15="","",T15) -> 1 | K15: 0.9559 | L15: =IF(F15="","",I15*J15) -> 10 | M15: =IF(B15="","",ROUND(SUM(L15*K15),3)) -> 9.559 | N15: =IFERROR((K15-0.0011)*L15,0) -> 9.548 | O15: =IF(E15="","",E15-15) -> 0 | P15: =K15*1000 -> 955.9 | Q15: =IF(K15>0.8385,186.9696,IF(K15>0.7875,594.5418,IF(K15>0.77,2680.3206,346.4228))) -> 186.9696 | R15: =IF(K15>0.8385,0.4862,IF(K15>0.7875,0,IF(K15>0.77,-0.00336312,0.4388))) -> 0.4862 | S15: =IF(OR(K15>0.7876,K15=0.7876),(Q15/P15^2)+(R15/P15),IF(OR(K15>0.7701,K15=0.7701),(Q15/P15^2)+R15,(Q15/P15^2)+(R15/P15))) -> 0.00071324967 | T15: =ROUND(EXP(-S15*O15*(1+0.8*S15*O15)),4) -> 1
B16: HFO 1S | C16: R HS | D16: 1 | E16: 15 | F16: 10 | G16: Nil | H16: 0 | I16: =IF(F16="","",F16-H16) -> 10 | J16: =IF(F16="","",T16) -> 1 | K16: 0.9559 | L16: =IF(F16="","",I16*J16) -> 10 | M16: =IF(B16="","",ROUND(SUM(L16*K16),3)) -> 9.559 | N16: =IFERROR((K16-0.0011)*L16,0) -> 9.548 | O16: =IF(E16="","",E16-15) -> 0 | P16: =K16*1000 -> 955.9 | Q16: =IF(K16>0.8385,186.9696,IF(K16>0.7875,594.5418,IF(K16>0.77,2680.3206,346.4228))) -> 186.9696 | R16: =IF(K16>0.8385,0.4862,IF(K16>0.7875,0,IF(K16>0.77,-0.00336312,0.4388))) -> 0.4862 | S16: =IF(OR(K16>0.7876,K16=0.7876),(Q16/P16^2)+(R16/P16),IF(OR(K16>0.7701,K16=0.7701),(Q16/P16^2)+R16,(Q16/P16^2)+(R16/P16))) -> 0.00071324967 | T16: =ROUND(EXP(-S16*O16*(1+0.8*S16*O16)),4) -> 1
B17: HFO 2P | C17: R HS | D17: 1 | E17: 15 | F17: 10 | G17: Nil | H17: 0 | I17: =IF(F17="","",F17-H17) -> 10 | J17: =IF(F17="","",T17) -> 1 | K17: 0.9559 | L17: =IF(F17="","",I17*J17) -> 10 | M17: =IF(B17="","",ROUND(SUM(L17*K17),3)) -> 9.559 | N17: =IFERROR((K17-0.0011)*L17,0) -> 9.548 | O17: =IF(E17="","",E17-15) -> 0 | P17: =K17*1000 -> 955.9 | Q17: =IF(K17>0.8385,186.9696,IF(K17>0.7875,594.5418,IF(K17>0.77,2680.3206,346.4228))) -> 186.9696 | R17: =IF(K17>0.8385,0.4862,IF(K17>0.7875,0,IF(K17>0.77,-0.00336312,0.4388))) -> 0.4862 | S17: =IF(OR(K17>0.7876,K17=0.7876),(Q17/P17^2)+(R17/P17),IF(OR(K17>0.7701,K17=0.7701),(Q17/P17^2)+R17,(Q17/P17^2)+(R17/P17))) -> 0.00071324967 | T17: =ROUND(EXP(-S17*O17*(1+0.8*S17*O17)),4) -> 1
B18: HFO 2S | C18: R HS | D18: 1 | E18: 15 | F18: 10 | G18: Nil | H18: 0 | I18: =IF(F18="","",F18-H18) -> 10 | J18: =IF(F18="","",T18) -> 1 | K18: 0.9559 | L18: =IF(F18="","",I18*J18) -> 10 | M18: =IF(B18="","",ROUND(SUM(L18*K18),3)) -> 9.559 | N18: =IFERROR((K18-0.0011)*L18,0) -> 9.548 | O18: =IF(E18="","",E18-15) -> 0 | P18: =K18*1000 -> 955.9 | Q18: =IF(K18>0.8385,186.9696,IF(K18>0.7875,594.5418,IF(K18>0.77,2680.3206,346.4228))) -> 186.9696 | R18: =IF(K18>0.8385,0.4862,IF(K18>0.7875,0,IF(K18>0.77,-0.00336312,0.4388))) -> 0.4862 | S18: =IF(OR(K18>0.7876,K18=0.7876),(Q18/P18^2)+(R18/P18),IF(OR(K18>0.7701,K18=0.7701),(Q18/P18^2)+R18,(Q18/P18^2)+(R18/P18))) -> 0.00071324967 | T18: =ROUND(EXP(-S18*O18*(1+0.8*S18*O18)),4) -> 1
B19: HFO 3P | C19: R HS | D19: 1 | E19: 15 | F19: 10 | G19: Nil | H19: 0 | I19: =IF(F19="","",F19-H19) -> 10 | J19: =IF(F19="","",T19) -> 1 | K19: 0.9559 | L19: =IF(F19="","",I19*J19) -> 10 | M19: =IF(B19="","",ROUND(SUM(L19*K19),3)) -> 9.559 | N19: =IFERROR((K19-0.0011)*L19,0) -> 9.548 | O19: =IF(E19="","",E19-15) -> 0 | P19: =K19*1000 -> 955.9 | Q19: =IF(K19>0.8385,186.9696,IF(K19>0.7875,594.5418,IF(K19>0.77,2680.3206,346.4228))) -> 186.9696 | R19: =IF(K19>0.8385,0.4862,IF(K19>0.7875,0,IF(K19>0.77,-0.00336312,0.4388))) -> 0.4862 | S19: =IF(OR(K19>0.7876,K19=0.7876),(Q19/P19^2)+(R19/P19),IF(OR(K19>0.7701,K19=0.7701),(Q19/P19^2)+R19,(Q19/P19^2)+(R19/P19))) -> 0.00071324967 | T19: =ROUND(EXP(-S19*O19*(1+0.8*S19*O19)),4) -> 1
B20: HFO 3S | C20: R HS | D20: 11.07 | E20: 15 | F20: 10 | G20: Nil | H20: 0 | I20: =IF(F20="","",F20-H20) -> 10 | J20: =IF(F20="","",T20) -> 1 | K20: 0.9559 | L20: =IF(F20="","",I20*J20) -> 10 | M20: =IF(B20="","",ROUND(SUM(L20*K20),3)) -> 9.559 | N20: =IFERROR((K20-0.0011)*L20,0) -> 9.548 | O20: =IF(E20="","",E20-15) -> 0 | P20: =K20*1000 -> 955.9 | Q20: =IF(K20>0.8385,186.9696,IF(K20>0.7875,594.5418,IF(K20>0.77,2680.3206,346.4228))) -> 186.9696 | R20: =IF(K20>0.8385,0.4862,IF(K20>0.7875,0,IF(K20>0.77,-0.00336312,0.4388))) -> 0.4862 | S20: =IF(OR(K20>0.7876,K20=0.7876),(Q20/P20^2)+(R20/P20),IF(OR(K20>0.7701,K20=0.7701),(Q20/P20^2)+R20,(Q20/P20^2)+(R20/P20))) -> 0.00071324967 | T20: =ROUND(EXP(-S20*O20*(1+0.8*S20*O20)),4) -> 1
B21: HFO 3O | C21: R HS | D21: 17.11 | E21: 15 | F21: 10 | G21: Nil | H21: 0 | I21: =IF(F21="","",F21-H21) -> 10 | J21: =IF(F21="","",T21) -> 1 | K21: 0.976 | L21: =IF(F21="","",I21*J21) -> 10 | M21: =IF(B21="","",ROUND(SUM(L21*K21),3)) -> 9.76 | N21: =IFERROR((K21-0.0011)*L21,0) -> 9.749 | O21: =IF(E21="","",E21-15) -> 0 | P21: =K21*1000 -> 976 | Q21: =IF(K21>0.8385,186.9696,IF(K21>0.7875,594.5418,IF(K21>0.77,2680.3206,346.4228))) -> 186.9696 | R21: =IF(K21>0.8385,0.4862,IF(K21>0.7875,0,IF(K21>0.77,-0.00336312,0.4388))) -> 0.4862 | S21: =IF(OR(K21>0.7876,K21=0.7876),(Q21/P21^2)+(R21/P21),IF(OR(K21>0.7701,K21=0.7701),(Q21/P21^2)+R21,(Q21/P21^2)+(R21/P21))) -> 0.00069443362 | T21: =ROUND(EXP(-S21*O21*(1+0.8*S21*O21)),4) -> 1
B22: HFO 3S | C22: R HS | D22: 10.1 | E22: 15 | F22: 10 | G22: Nil | H22: 0 | I22: =IF(F22="","",F22-H22) -> 10 | J22: =IF(F22="","",T22) -> 1 | K22: 0.9557 | L22: =IF(F22="","",I22*J22) -> 10 | M22: =IF(B22="","",ROUND(SUM(L22*K22),3)) -> 9.557 | N22: =IFERROR((K22-0.0011)*L22,0) -> 9.546 | O22: =IF(E22="","",E22-15) -> 0 | P22: =K22*1000 -> 955.7 | Q22: =IF(K22>0.8385,186.9696,IF(K22>0.7875,594.5418,IF(K22>0.77,2680.3206,346.4228))) -> 186.9696 | R22: =IF(K22>0.8385,0.4862,IF(K22>0.7875,0,IF(K22>0.77,-0.00336312,0.4388))) -> 0.4862 | S22: =IF(OR(K22>0.7876,K22=0.7876),(Q22/P22^2)+(R22/P22),IF(OR(K22>0.7701,K22=0.7701),(Q22/P22^2)+R22,(Q22/P22^2)+(R22/P22))) -> 0.00071344176 | T22: =ROUND(EXP(-S22*O22*(1+0.8*S22*O22)),4) -> 1
B23: HFO 4P | C23: R HS | D23: 0,18 (S) | E23: 15 | F23: 10 | G23: Nil | H23: 0 | I23: =IF(F23="","",F23-H23) -> 10 | J23: =IF(F23="","",T23) -> 1 | K23: 0.976 | L23: =IF(F23="","",I23*J23) -> 10 | M23: =IF(B23="","",ROUND(SUM(L23*K23),3)) -> 9.76 | N23: =IFERROR((K23-0.0011)*L23,0) -> 9.749 | O23: =IF(E23="","",E23-15) -> 0 | P23: =K23*1000 -> 976 | Q23: =IF(K23>0.8385,186.9696,IF(K23>0.7875,594.5418,IF(K23>0.77,2680.3206,346.4228))) -> 186.9696 | R23: =IF(K23>0.8385,0.4862,IF(K23>0.7875,0,IF(K23>0.77,-0.00336312,0.4388))) -> 0.4862 | S23: =IF(OR(K23>0.7876,K23=0.7876),(Q23/P23^2)+(R23/P23),IF(OR(K23>0.7701,K23=0.7701),(Q23/P23^2)+R23,(Q23/P23^2)+(R23/P23))) -> 0.00069443362 | T23: =ROUND(EXP(-S23*O23*(1+0.8*S23*O23)),4) -> 1
B24: HFO 4S | C24: R HS | D24: 0,12 (S) | E24: 15 | F24: 10 | G24: Nil | H24: 0 | I24: =IF(F24="","",F24-H24) -> 10 | J24: =IF(F24="","",T24) -> 1 | K24: 0.9367 | L24: =IF(F24="","",I24*J24) -> 10 | M24: =IF(B24="","",ROUND(SUM(L24*K24),3)) -> 9.367 | N24: =IFERROR((K24-0.0011)*L24,0) -> 9.356 | O24: =IF(E24="","",E24-15) -> 0 | P24: =K24*1000 -> 936.7 | Q24: =IF(K24>0.8385,186.9696,IF(K24>0.7875,594.5418,IF(K24>0.77,2680.3206,346.4228))) -> 186.9696 | R24: =IF(K24>0.8385,0.4862,IF(K24>0.7875,0,IF(K24>0.77,-0.00336312,0.4388))) -> 0.4862 | S24: =IF(OR(K24>0.7876,K24=0.7876),(Q24/P24^2)+(R24/P24),IF(OR(K24>0.7701,K24=0.7701),(Q24/P24^2)+R24,(Q24/P24^2)+(R24/P24))) -> 0.00073214964 | T24: =ROUND(EXP(-S24*O24*(1+0.8*S24*O24)),4) -> 1
B25: HFO 5P | C25: R HS | D25: 0,22 (S) | E25: 15 | F25: 10 | G25: Nil | H25: 0 | I25: =IF(F25="","",F25-H25) -> 10 | J25: =IF(F25="","",T25) -> 1 | K25: 0.9557 | L25: =IF(F25="","",I25*J25) -> 10 | M25: =IF(B25="","",ROUND(SUM(L25*K25),3)) -> 9.557 | N25: =IFERROR((K25-0.0011)*L25,0) -> 9.546 | O25: =IF(E25="","",E25-15) -> 0 | P25: =K25*1000 -> 955.7 | Q25: =IF(K25>0.8385,186.9696,IF(K25>0.7875,594.5418,IF(K25>0.77,2680.3206,346.4228))) -> 186.9696 | R25: =IF(K25>0.8385,0.4862,IF(K25>0.7875,0,IF(K25>0.77,-0.00336312,0.4388))) -> 0.4862 | S25: =IF(OR(K25>0.7876,K25=0.7876),(Q25/P25^2)+(R25/P25),IF(OR(K25>0.7701,K25=0.7701),(Q25/P25^2)+R25,(Q25/P25^2)+(R25/P25))) -> 0.00071344176 | T25: =ROUND(EXP(-S25*O25*(1+0.8*S25*O25)),4) -> 1
B26: HFO 5S | C26: R HS | D26: 0,10 (S) | E26: 15 | F26: 10 | G26: Nil | H26: 0 | I26: =IF(F26="","",F26-H26) -> 10 | J26: =IF(F26="","",T26) -> 1 | K26: 0.9557 | L26: =IF(F26="","",I26*J26) -> 10 | M26: =IF(B26="","",ROUND(SUM(L26*K26),3)) -> 9.557 | N26: =IFERROR((K26-0.0011)*L26,0) -> 9.546 | O26: =IF(E26="","",E26-15) -> 0 | P26: =K26*1000 -> 955.7 | Q26: =IF(K26>0.8385,186.9696,IF(K26>0.7875,594.5418,IF(K26>0.77,2680.3206,346.4228))) -> 186.9696 | R26: =IF(K26>0.8385,0.4862,IF(K26>0.7875,0,IF(K26>0.77,-0.00336312,0.4388))) -> 0.4862 | S26: =IF(OR(K26>0.7876,K26=0.7876),(Q26/P26^2)+(R26/P26),IF(OR(K26>0.7701,K26=0.7701),(Q26/P26^2)+R26,(Q26/P26^2)+(R26/P26))) -> 0.00071344176 | T26: =ROUND(EXP(-S26*O26*(1+0.8*S26*O26)),4) -> 1
B27: HFO SERV 1 | C27: R VLS | D27: 9.94 | E27: 15 | F27: 100 | G27: Nil | H27: 0 | I27: =IF(F27="","",F27-H27) -> 100 | J27: =IF(F27="","",T27) -> 1 | K27: 0.9557 | L27: =IF(F27="","",I27*J27) -> 100 | M27: =IF(B27="","",ROUND(SUM(L27*K27),3)) -> 95.57 | N27: =IFERROR((K27-0.0011)*L27,0) -> 95.46 | O27: =IF(E27="","",E27-15) -> 0 | P27: =K27*1000 -> 955.7 | Q27: =IF(K27>0.8385,186.9696,IF(K27>0.7875,594.5418,IF(K27>0.77,2680.3206,346.4228))) -> 186.9696 | R27: =IF(K27>0.8385,0.4862,IF(K27>0.7875,0,IF(K27>0.77,-0.00336312,0.4388))) -> 0.4862 | S27: =IF(OR(K27>0.7876,K27=0.7876),(Q27/P27^2)+(R27/P27),IF(OR(K27>0.7701,K27=0.7701),(Q27/P27^2)+R27,(Q27/P27^2)+(R27/P27))) -> 0.00071344176 | T27: =ROUND(EXP(-S27*O27*(1+0.8*S27*O27)),4) -> 1
B28: HFO SETT 1 | C28: R VLS | D28: 0,03 (S) | E28: 15 | F28: 100 | G28: Nil | H28: 0 | I28: =IF(F28="","",F28-H28) -> 100 | J28: =IF(F28="","",T28) -> 1 | K28: 0.978 | L28: =IF(F28="","",I28*J28) -> 100 | M28: =IF(B28="","",ROUND(SUM(L28*K28),3)) -> 97.8 | N28: =IFERROR((K28-0.0011)*L28,0) -> 97.69 | O28: =IF(E28="","",E28-15) -> 0 | P28: =K28*1000 -> 978 | Q28: =IF(K28>0.8385,186.9696,IF(K28>0.7875,594.5418,IF(K28>0.77,2680.3206,346.4228))) -> 186.9696 | R28: =IF(K28>0.8385,0.4862,IF(K28>0.7875,0,IF(K28>0.77,-0.00336312,0.4388))) -> 0.4862 | S28: =IF(OR(K28>0.7876,K28=0.7876),(Q28/P28^2)+(R28/P28),IF(OR(K28>0.7701,K28=0.7701),(Q28/P28^2)+R28,(Q28/P28^2)+(R28/P28))) -> 0.00069261294 | T28: =ROUND(EXP(-S28*O28*(1+0.8*S28*O28)),4) -> 1
B29: HFO SERV 2 | C29: R VLS | D29: 2.97 | E29: 15 | F29: 100 | G29: Nil | H29: 0 | I29: =IF(F29="","",F29-H29) -> 100 | J29: =IF(F29="","",T29) -> 1 | K29: 0.978 | L29: =IF(F29="","",I29*J29) -> 100 | M29: =IF(B29="","",ROUND(SUM(L29*K29),3)) -> 97.8 | N29: =IFERROR((K29-0.0011)*L29,0) -> 97.69 | O29: =IF(E29="","",E29-15) -> 0 | P29: =K29*1000 -> 978 | Q29: =IF(K29>0.8385,186.9696,IF(K29>0.7875,594.5418,IF(K29>0.77,2680.3206,346.4228))) -> 186.9696 | R29: =IF(K29>0.8385,0.4862,IF(K29>0.7875,0,IF(K29>0.77,-0.00336312,0.4388))) -> 0.4862 | S29: =IF(OR(K29>0.7876,K29=0.7876),(Q29/P29^2)+(R29/P29),IF(OR(K29>0.7701,K29=0.7701),(Q29/P29^2)+R29,(Q29/P29^2)+(R29/P29))) -> 0.00069261294 | T29: =ROUND(EXP(-S29*O29*(1+0.8*S29*O29)),4) -> 1
B30: HFO SERTT 2 | C30: R VLS | D30: 2.09 | E30: 15 | F30: 100 | G30: Nil | H30: 0 | I30: =IF(F30="","",F30-H30) -> 100 | J30: =IF(F30="","",T30) -> 1 | K30: 0.978 | L30: =IF(F30="","",I30*J30) -> 100 | M30: =IF(B30="","",ROUND(SUM(L30*K30),3)) -> 97.8 | N30: =IFERROR((K30-0.0011)*L30,0) -> 97.69 | O30: =IF(E30="","",E30-15) -> 0 | P30: =K30*1000 -> 978 | Q30: =IF(K30>0.8385,186.9696,IF(K30>0.7875,594.5418,IF(K30>0.77,2680.3206,346.4228))) -> 186.9696 | R30: =IF(K30>0.8385,0.4862,IF(K30>0.7875,0,IF(K30>0.77,-0.00336312,0.4388))) -> 0.4862 | S30: =IF(OR(K30>0.7876,K30=0.7876),(Q30/P30^2)+(R30/P30),IF(OR(K30>0.7701,K30=0.7701),(Q30/P30^2)+R30,(Q30/P30^2)+(R30/P30))) -> 0.00069261294 | T30: =ROUND(EXP(-S30*O30*(1+0.8*S30*O30)),4) -> 1
B31: HFO OFLOW | C31: R VLS | D31: 3.05 | E31: 15 | F31: 100 | G31: Nil | H31: 0 | I31: =IF(F31="","",F31-H31) -> 100 | J31: =IF(F31="","",T31) -> 1 | K31: 0.978 | L31: =IF(F31="","",I31*J31) -> 100 | M31: =IF(B31="","",ROUND(SUM(L31*K31),3)) -> 97.8 | N31: =IFERROR((K31-0.0011)*L31,0) -> 97.69 | O31: =IF(E31="","",E31-15) -> 0 | P31: =K31*1000 -> 978 | Q31: =IF(K31>0.8385,186.9696,IF(K31>0.7875,594.5418,IF(K31>0.77,2680.3206,346.4228))) -> 186.9696 | R31: =IF(K31>0.8385,0.4862,IF(K31>0.7875,0,IF(K31>0.77,-0.00336312,0.4388))) -> 0.4862 | S31: =IF(OR(K31>0.7876,K31=0.7876),(Q31/P31^2)+(R31/P31),IF(OR(K31>0.7701,K31=0.7701),(Q31/P31^2)+R31,(Q31/P31^2)+(R31/P31))) -> 0.00069261294 | T31: =ROUND(EXP(-S31*O31*(1+0.8*S31*O31)),4) -> 1
B32: VLSFO 6P | C32: R VLS | D32: 2.25 | E32: 15 | F32: 100 | G32: Nil | H32: 0 | I32: =IF(F32="","",F32-H32) -> 100 | J32: =IF(F32="","",T32) -> 1 | K32: 0.9557 | L32: =IF(F32="","",I32*J32) -> 100 | M32: =IF(B32="","",ROUND(SUM(L32*K32),3)) -> 95.57 | N32: =IFERROR((K32-0.0011)*L32,0) -> 95.46 | O32: =IF(E32="","",E32-15) -> 0 | P32: =K32*1000 -> 955.7 | Q32: =IF(K32>0.8385,186.9696,IF(K32>0.7875,594.5418,IF(K32>0.77,2680.3206,346.4228))) -> 186.9696 | R32: =IF(K32>0.8385,0.4862,IF(K32>0.7875,0,IF(K32>0.77,-0.00336312,0.4388))) -> 0.4862 | S32: =IF(OR(K32>0.7876,K32=0.7876),(Q32/P32^2)+(R32/P32),IF(OR(K32>0.7701,K32=0.7701),(Q32/P32^2)+R32,(Q32/P32^2)+(R32/P32))) -> 0.00071344176 | T32: =ROUND(EXP(-S32*O32*(1+0.8*S32*O32)),4) -> 1
B33: VLSFO 6S | C33: DIST | D33: 4,09 (S) | E33: 15 | F33: 1 | G33: Nil | H33: 0 | I33: =IF(F33="","",F33-H33) -> 1 | J33: =IF(F33="","",T33) -> 1 | K33: 0.8691 | L33: =IF(F33="","",I33*J33) -> 1 | M33: =IF(B33="","",ROUND(SUM(L33*K33),3)) -> 0.869 | N33: =IFERROR((K33-0.0011)*L33,0) -> 0.868 | O33: =IF(E33="","",E33-15) -> 0 | P33: =K33*1000 -> 869.1 | Q33: =IF(K33>0.8385,186.9696,IF(K33>0.7875,594.5418,IF(K33>0.77,2680.3206,346.4228))) -> 186.9696 | R33: =IF(K33>0.8385,0.4862,IF(K33>0.7875,0,IF(K33>0.77,-0.00336312,0.4388))) -> 0.4862 | S33: =IF(OR(K33>0.7876,K33=0.7876),(Q33/P33^2)+(R33/P33),IF(OR(K33>0.7701,K33=0.7701),(Q33/P33^2)+R33,(Q33/P33^2)+(R33/P33))) -> 0.00080696138 | T33: =ROUND(EXP(-S33*O33*(1+0.8*S33*O33)),4) -> 1
B34: VLSFO SERV | C34: DIST | D34: 9,26 (S) | E34: 15 | F34: 1 | G34: Nil | H34: 0 | I34: =IF(F34="","",F34-H34) -> 1 | J34: =IF(F34="","",T34) -> 1 | K34: 0.887 | L34: =IF(F34="","",I34*J34) -> 1 | M34: =IF(B34="","",ROUND(SUM(L34*K34),3)) -> 0.887 | N34: =IFERROR((K34-0.0011)*L34,0) -> 0.8859 | O34: =IF(E34="","",E34-15) -> 0 | P34: =K34*1000 -> 887 | Q34: =IF(K34>0.8385,186.9696,IF(K34>0.7875,594.5418,IF(K34>0.77,2680.3206,346.4228))) -> 186.9696 | R34: =IF(K34>0.8385,0.4862,IF(K34>0.7875,0,IF(K34>0.77,-0.00336312,0.4388))) -> 0.4862 | S34: =IF(OR(K34>0.7876,K34=0.7876),(Q34/P34^2)+(R34/P34),IF(OR(K34>0.7701,K34=0.7701),(Q34/P34^2)+R34,(Q34/P34^2)+(R34/P34))) -> 0.0007857821 | T34: =ROUND(EXP(-S34*O34*(1+0.8*S34*O34)),4) -> 1
B35: VLSFO SERV | C35: DIST | D35: 0,00 (S) | E35: 15 | F35: 1 | G35: Nil | H35: 0 | I35: =IF(F35="","",F35-H35) -> 1 | J35: =IF(F35="","",T35) -> 1 | K35: 0.8764 | L35: =IF(F35="","",I35*J35) -> 1 | M35: =IF(B35="","",ROUND(SUM(L35*K35),3)) -> 0.876 | N35: =IFERROR((K35-0.0011)*L35,0) -> 0.8753 | O35: =IF(E35="","",E35-15) -> 0 | P35: =K35*1000 -> 876.4 | Q35: =IF(K35>0.8385,186.9696,IF(K35>0.7875,594.5418,IF(K35>0.77,2680.3206,346.4228))) -> 186.9696 | R35: =IF(K35>0.8385,0.4862,IF(K35>0.7875,0,IF(K35>0.77,-0.00336312,0.4388))) -> 0.4862 | S35: =IF(OR(K35>0.7876,K35=0.7876),(Q35/P35^2)+(R35/P35),IF(OR(K35>0.7701,K35=0.7701),(Q35/P35^2)+R35,(Q35/P35^2)+(R35/P35))) -> 0.00079819512 | T35: =ROUND(EXP(-S35*O35*(1+0.8*S35*O35)),4) -> 1
B36: MDO P | C36: DIST | D36: GAUGE | E36: 15 | F36: 1 | G36: Nil | H36: 0 | I36: =IF(F36="","",F36-H36) -> 1 | J36: =IF(F36="","",T36) -> 1 | K36: 0.8764 | L36: =IF(F36="","",I36*J36) -> 1 | M36: =IF(B36="","",ROUND(SUM(L36*K36),3)) -> 0.876 | N36: =IFERROR((K36-0.0011)*L36,0) -> 0.8753 | O36: =IF(E36="","",E36-15) -> 0 | P36: =K36*1000 -> 876.4 | Q36: =IF(K36>0.8385,186.9696,IF(K36>0.7875,594.5418,IF(K36>0.77,2680.3206,346.4228))) -> 186.9696 | R36: =IF(K36>0.8385,0.4862,IF(K36>0.7875,0,IF(K36>0.77,-0.00336312,0.4388))) -> 0.4862 | S36: =IF(OR(K36>0.7876,K36=0.7876),(Q36/P36^2)+(R36/P36),IF(OR(K36>0.7701,K36=0.7701),(Q36/P36^2)+R36,(Q36/P36^2)+(R36/P36))) -> 0.00079819512 | T36: =ROUND(EXP(-S36*O36*(1+0.8*S36*O36)),4) -> 1
D37: GAUGE | E37: 15 | F37: 1 | G37: Nil | H37: 0 | I37: =IF(F37="","",F37-H37) -> 1 | J37: =IF(F37="","",T37) -> 1 | K37: 0.8764 | L37: =IF(F37="","",I37*J37) -> 1 | M37: =IF(B37="","",ROUND(SUM(L37*K37),3)) | N37: =IFERROR((K37-0.0011)*L37,0) -> 0.8753 | O37: =IF(E37="","",E37-15) -> 0 | P37: =K37*1000 -> 876.4 | Q37: =IF(K37>0.8385,186.9696,IF(K37>0.7875,594.5418,IF(K37>0.77,2680.3206,346.4228))) -> 186.9696 | R37: =IF(K37>0.8385,0.4862,IF(K37>0.7875,0,IF(K37>0.77,-0.00336312,0.4388))) -> 0.4862 | S37: =IF(OR(K37>0.7876,K37=0.7876),(Q37/P37^2)+(R37/P37),IF(OR(K37>0.7701,K37=0.7701),(Q37/P37^2)+R37,(Q37/P37^2)+(R37/P37))) -> 0.00079819512 | T37: =ROUND(EXP(-S37*O37*(1+0.8*S37*O37)),4) -> 1
D38: GAUGE | E38: 15 | F38: 1 | G38: Nil | H38: 0 | I38: =IF(F38="","",F38-H38) -> 1 | J38: =IF(F38="","",T38) -> 1 | K38: 0.8764 | L38: =IF(F38="","",I38*J38) -> 1 | M38: =IF(B38="","",ROUND(SUM(L38*K38),3)) | N38: =IFERROR((K38-0.0011)*L38,0) -> 0.8753 | O38: =IF(E38="","",E38-15) -> 0 | P38: =K38*1000 -> 876.4 | Q38: =IF(K38>0.8385,186.9696,IF(K38>0.7875,594.5418,IF(K38>0.77,2680.3206,346.4228))) -> 186.9696 | R38: =IF(K38>0.8385,0.4862,IF(K38>0.7875,0,IF(K38>0.77,-0.00336312,0.4388))) -> 0.4862 | S38: =IF(OR(K38>0.7876,K38=0.7876),(Q38/P38^2)+(R38/P38),IF(OR(K38>0.7701,K38=0.7701),(Q38/P38^2)+R38,(Q38/P38^2)+(R38/P38))) -> 0.00079819512 | T38: =ROUND(EXP(-S38*O38*(1+0.8*S38*O38)),4) -> 1
D39: GAUGE | E39: 15 | F39: 1 | G39: Nil | H39: 0 | I39: =IF(F39="","",F39-H39) -> 1 | J39: =IF(F39="","",T39) -> 1 | K39: 0.8764 | L39: =IF(F39="","",I39*J39) -> 1 | M39: =IF(B39="","",ROUND(SUM(L39*K39),3)) | N39: =IFERROR((K39-0.0011)*L39,0) -> 0.8753 | O39: =IF(E39="","",E39-15) -> 0 | P39: =K39*1000 -> 876.4 | Q39: =IF(K39>0.8385,186.9696,IF(K39>0.7875,594.5418,IF(K39>0.77,2680.3206,346.4228))) -> 186.9696 | R39: =IF(K39>0.8385,0.4862,IF(K39>0.7875,0,IF(K39>0.77,-0.00336312,0.4388))) -> 0.4862 | S39: =IF(OR(K39>0.7876,K39=0.7876),(Q39/P39^2)+(R39/P39),IF(OR(K39>0.7701,K39=0.7701),(Q39/P39^2)+R39,(Q39/P39^2)+(R39/P39))) -> 0.00079819512 | T39: =ROUND(EXP(-S39*O39*(1+0.8*S39*O39)),4) -> 1
D40: 1 | E40: 15 | F40: 1 | G40: Nil | H40: 0 | I40: =IF(F40="","",F40-H40) -> 1 | J40: =IF(F40="","",T40) -> 1 | K40: 1 | L40: =IF(F40="","",I40*J40) -> 1 | M40: =IF(B40="","",ROUND(SUM(L40*K40),3)) | N40: =IFERROR((K40-0.0011)*L40,0) -> 0.9989 | O40: =IF(E40="","",E40-15) -> 0 | P40: =K40*1000 -> 1000 | Q40: =IF(K40>0.8385,186.9696,IF(K40>0.7875,594.5418,IF(K40>0.77,2680.3206,346.4228))) -> 186.9696 | R40: =IF(K40>0.8385,0.4862,IF(K40>0.7875,0,IF(K40>0.77,-0.00336312,0.4388))) -> 0.4862 | S40: =IF(OR(K40>0.7876,K40=0.7876),(Q40/P40^2)+(R40/P40),IF(OR(K40>0.7701,K40=0.7701),(Q40/P40^2)+R40,(Q40/P40^2)+(R40/P40))) -> 0.0006731696 | T40: =ROUND(EXP(-S40*O40*(1+0.8*S40*O40)),4) -> 1
D41: 1 | E41: 15 | F41: 1 | G41: Nil | H41: 0 | I41: =IF(F41="","",F41-H41) -> 1 | J41: =IF(F41="","",T41) -> 1 | K41: 1 | L41: =IF(F41="","",I41*J41) -> 1 | M41: =IF(B41="","",ROUND(SUM(L41*K41),3)) | N41: =IFERROR((K41-0.0011)*L41,0) -> 0.9989 | O41: =IF(E41="","",E41-15) -> 0 | P41: =K41*1000 -> 1000 | Q41: =IF(K41>0.8385,186.9696,IF(K41>0.7875,594.5418,IF(K41>0.77,2680.3206,346.4228))) -> 186.9696 | R41: =IF(K41>0.8385,0.4862,IF(K41>0.7875,0,IF(K41>0.77,-0.00336312,0.4388))) -> 0.4862 | S41: =IF(OR(K41>0.7876,K41=0.7876),(Q41/P41^2)+(R41/P41),IF(OR(K41>0.7701,K41=0.7701),(Q41/P41^2)+R41,(Q41/P41^2)+(R41/P41))) -> 0.0006731696 | T41: =ROUND(EXP(-S41*O41*(1+0.8*S41*O41)),4) -> 1
D42: 1 | E42: 15 | F42: 1 | G42: Nil | H42: 0 | I42: =IF(F42="","",F42-H42) -> 1 | J42: =IF(F42="","",T42) -> 1 | K42: 1 | L42: =IF(F42="","",I42*J42) -> 1 | M42: =IF(B42="","",ROUND(SUM(L42*K42),3)) | N42: =IFERROR((K42-0.0011)*L42,0) -> 0.9989 | O42: =IF(E42="","",E42-15) -> 0 | P42: =K42*1000 -> 1000 | Q42: =IF(K42>0.8385,186.9696,IF(K42>0.7875,594.5418,IF(K42>0.77,2680.3206,346.4228))) -> 186.9696 | R42: =IF(K42>0.8385,0.4862,IF(K42>0.7875,0,IF(K42>0.77,-0.00336312,0.4388))) -> 0.4862 | S42: =IF(OR(K42>0.7876,K42=0.7876),(Q42/P42^2)+(R42/P42),IF(OR(K42>0.7701,K42=0.7701),(Q42/P42^2)+R42,(Q42/P42^2)+(R42/P42))) -> 0.0006731696 | T42: =ROUND(EXP(-S42*O42*(1+0.8*S42*O42)),4) -> 1
B43: Total R HS | I43: =SUMIF($C$15:$C$42,"R HS",$I$15:$I$42) -> 120 | L43: =SUMIF($C$15:$C$42,"R HS",$L$15:$L$42) -> 120 | M43: =SUMIF($C$15:$C$44,"R HS",$M$15:$M$42) -> 114.912 | N43: =SUMIF($C$15:$C$42,"R HS",$N$15:$N$42) -> 114.78 | O43: =SUM(O15:O42) -> 0
B44: Total R VLS | I44: =SUMIF($C$15:$C$42,"R VLS",$I$15:$I$42) -> 600 | L44: =SUMIF($C$15:$C$42,"R VLS",$L$15:$L$42) -> 600 | M44: =SUMIF($C$15:$C$44,"R VLS",$M$15:$M$42) -> 582.34 | N44: =SUMIF($C$15:$C$42,"R VLS",$N$15:$N$42) -> 581.68
B45: Total DIST | I45: =SUMIF($C$15:$C$42,"DIST",$I$15:$I$42) -> 4 | L45: =SUMIF($C$15:$C$42,"DIST",$L$15:$L$42) -> 4 | M45: =SUMIF($C$15:$C$42,"DIST",$M$15:$M$42) -> 3.508 | N45: =SUMIF($C$15:$C$42,"DIST",$N$15:$N$42) -> 3.5045
K47: VRS | L47: Survey | M47: Diff | N47: %
...

Sheet LOG Audit
A3: CONSUMPTION REPORT
B5: Name of Vessel | D5: =Summary!B7 -> MSC SABRINA | G5: IMO | I5: =Summary!B21 -> 9979022 | K5: VOY | L5: =Summary!B8 -> MM623R
B6: Location of Survey | D6: =Summary!B13 -> TERMINAL DE CONTAINER DE PARANAGUA | G6: Started | H6: ='Vessel Ullage'!J5 -> 46188 | J6: ='Time Log'!G7 -> 0.5 | K6: h
B7: Port | D7: =Summary!B14 -> PARANAGUA | G7: Completed | H7: ='Time Log'!F14 -> 46189 | J7: ='Time Log'!I14 -> 0.041666667 | K7: h
B11: LOG BOOK AUDIT | C11: Logbook (MT) | D11: Bunkering * (MT) | E11: Logbook ROB (MT) | F11: Others (MT) | G11: Adjusted (MT) | H11: Consump (MT) | J11: Berthing message
C12: =Sludge!D27 -> 46157 | E12: 46249 | J12: =Summary!B18 -> 46249 | K12: =Summary!B19 -> 0.83333333
B13: =Summary!B9 -> R HS | C13: 150 | D13: 10 | E13: 120 | F13: 0 | G13: 0 | H13: =(C13+D13)-E13 -> 40 | J13: 151
B14: =Summary!B10 -> R VLS | C14: 160 | D14: 10 | E14: 110 | F14: 0 | G14: 0 | H14: =(C14+D14)-E14 -> 60 | J14: 161
B15: =Summary!B11 -> DISTILLATES | C15: 170 | D15: 10 | E15: 100 | F15: 0 | G15: 0 | H15: =(C15+D15)-E15 -> 80 | J15: 171
B16: TOTAL | C16: =SUM(C13:C15) -> 480 | D16: =SUM(D13:D15) -> 30 | E16: =SUM(E13:E15) -> 330 | F16: =SUM(F13:F15) -> 0 | G16: =SUM(G13:G15) -> 0 | H16: =SUM(H13:H15) -> 180 | J16: =SUM(J13:J15) -> 483
B18: Bunkering * | C18: Grade | D18: Date | E18: Place | F18: BDN nº | G18: Quantity (MT)
B19: 1 | C19: LSMGO | D19: 46104 | E19: CHINA | F19: - | G19: 200
B20: 2 | C20: VLSFO | D20: 46105 | E20: CHINA | F20: - | G20: 600
B21: 3 | C21: VLSFO | D21: 46105 | E21: CHINA | F21: - | G21: 397
B22: 4 | C22: LSMGO | D22: 46137 | E22: SINGAPORE | F22: - | G22: 198.661
B23: 5 | C23: VLSFO | D23: 46137 | E23: SINGAPORE | F23: - | G23: 1597.25
B24: 6 | C24: VLSFO | D24: 46168 | E24: SANTOS/BRAZIL | F24: - | G24: 400.028
B26: FLOWMETERS READINGS | E26: TYPE: | F26: DIGITAL FLOWMETER
B27: Readings | C27: Grades | D27: Main Enginee | E27: Auxiliar Enginee | F27: Boiler | G27: Comments
B28: =C12 -> 46157 | C28: FO/DO | D28: 188143 | E28: 172110 | F28: 9412 | G28: Previous Survey
B29: =E12 -> 46249 | C29: FO/DO | D29: 3008904 | E29: 306338 | F29: 9965 | G29: Actual survey
C30: Dif (m3) | D30: =(D29-D28)/1000 -> 2820.761 | E30: =(E29-E28)/1000 -> 134.228 | F30: =(F29-F28)/1000 -> 0.553
C31: S.G. | D31: 0.9898 | E31: 0.9898 | F31: 0.9898
C32: TOTAL (MT) | D32: =D30*D31 -> 2791.9892 | E32: =E30*E31 -> 132.85887 | F32: =F30*F31 -> 0.5473594
B34: TOTAL CONSUMPTIONS SINCE LAST DISPOSAL SLUDGE SURVEY
B36: Per Logbook | D36: Total | E36: =H16 -> 180 | F36: MT
B37: Per Flowmeter | D37: Total | E37: =D32+E32+F32 -> 2925.3955 | F37: MT
B38: Flowmeter Discrepancy | E38: =E37-E36 -> 2745.3955 | F38: MT
B39: Flowmeter Accourancy | E39: =IFERROR(E38/E37*100,0) -> 93.846986 | F39: %
B42: REMARKS:
B57: CHIEF ENGINEER: | D57: =Summary!B38 -> SIBI JESU ANTHONY | H57: SURVEYOR: | J57: =Summary!B15 -> ARMANDO JUNIOR

Sheet LNG
B3: LNG - Measuremente Report
B5: Name of Vessel | D5: =Summary!B7 -> MSC SABRINA | G5: IMO | H5: =Summary!B21 -> 9979022 | I5: VOY | J5: =Summary!B8 -> MM623R
B6: Location of Survey | D6: =Summary!B13 -> TERMINAL DE CONTAINER DE PARANAGUA | G6: Started | H6: ='Vessel Ullage'!J5 -> 46188 | I6: ='Time Log'!G7 -> 0.5 | J6: h
B7: Port | D7: =Summary!B14 -> PARANAGUA | G7: Completed | H7: ='Time Log'!F14 -> 46189 | I7: ='Time Log'!I14 -> 0.041666667 | J7: h
B11: Tank Name | C11: 1 | E11: 2 | G11: 3 | I11: 4 | K11: 5 | M11: 6
B12: Tank Capacity ( m³) | C12: 8034.5
B14: Temp (Kelvin) | C14: Liquid | D14: Vapour | E14: Liquid | F14: Vapour | G14: Liquid | H14: Vapour | I14: Liquid | J14: Vapour | K14: Liquid | L14: Vapour | M14: Liquid | N14: Vapour
B15: Temp sensor 1 | D15: -137
B16: Temp sensor 2 | D16: -147
B17: Temp sensor 3 | C17: -159
B18: Temp sensor 4 | C18: -159
B19: Temp sensor 5
B20: Temp sensor 6
B22: Average Temp (Kelvin) | C22: =AVERAGE(C15:C20)+273.15 -> 114.15 | D22: =AVERAGE(D15:D20)+273.15 -> 131.15
B24: Average Press (Pa) | C24: 814000
B25: Average Level | C25: 16.58
B26: Corrected Volume | C26: 4976
B28: REPORT OF ANALYSIS
B29: Component (i) | D29: CH4 | E29: C2H6 | F29: C3H8 | G29: i C4H10 | H29: n C4H10 | I29: i C5H12 | J29: n C5H12 | K29: N2 | L29: n C6H14 | M29: C02 | N29: O2
B30: Molecular Weight (Mi) | D30: 16.0425 | E30: 30.069 | F30: 44.0956 | G30: 58.1222 | H30: 58.1222 | I30: 72.1488 | J30: 72.1488 | K30: 28.0134 | L30: 86.1754 | M30: 44.0095 | N30: 31.9988
B31: Mole fraction (Xi) | D31: 0.9046 | E31: 0.0703 | F31: 0.0167 | G31: 0.0031 | H31: 0.0046 | I31: 0.0002 | J31: 0.0001 | K31: 0.0004 | L31: 0 | M31: 0 | N31: 0
B32: MiXi | D32: =D30*D31 -> 14.512045 | E32: =E30*E31 -> 2.1138507 | F32: =F30*F31 -> 0.73639652 | G32: =G30*G31 -> 0.18017882 | H32: =H30*H31 -> 0.26736212 | I32: =I30*I31 -> 0.01442976 | J32: =J30*J31 -> 0.00721488 | K32: =K30*K31 -> 0.01120536 | ... N32: =N30*N31 -> 0
K33: ΣxiMi | N33: =SUM(D32:N32) -> 17.842684
B34: MMIX | C34: =SUM(D32:N32) -> 17.842684 | D34: g/mol
B35: VMIX | C35: 0.03955 | D35: l/mol
B36: DLNG | C36: =C34/C35/1000 -> 0.45114244 | D36: kg/m³
B37: MLIQUID | C37: 2244.89 | D37: mt
B38: MGAS | C38: 40.737 | D38: mt
B39: M | C39: =C37+C38 -> 2285.627 | D39: mt
B40: Berthing message | C40: 2280 | D40: mt
B41: Difference | C41: =C39-C40 -> 5.627 | D41: mt
C42: =(C41/C40)*100 -> 0.24679825 | D42: %
B44: LOG BOOK AUDIT | C44: Logbook (MT) | D44: Bunkering (MT) | E44: Logbook ROB (MT) | F44: Others (MT) | G44: Adjusted (MT) | H44: Logbook Consump (MT) | J44: Berthing Report
C45: ='LOG Audit'!C12 -> 46157 | E45: ='LOG Audit'!E12 -> 46249 | J45: =Summary!B18 -> 46249 | K45: =Summary!B19 -> 0.83333333
B46: LNG | C46: 672.1 | D46: 2237.869 | E46: 2317.25 | F46: 0 | G46: 0 | H46: =(C46+D46)-E46 -> 592.719 | J46: 2317.25
B47: TOTAL | C47: =SUM(C46:C46) -> 672.1 | D47: =SUM(D46:D46) -> 2237.869 | E47: =SUM(E46:E46) -> 2317.25 | F47: =SUM(F46:F46) -> 0 | G47: =SUM(G46:G46) -> 0 | H47: =SUM(H46:H46) -> 592.719 | J47: =J46 -> 2317.25
B49: FLOWMETERS READINGS | E49: TYPE: | F49: DIGITAL FLOWMETER
B50: Readings | C50: Grades | D50: Main Enginee | E50: Auxiliar Enginee 1 | F50: Auxiliar Enginee 2 | G50: Auxiliar Enginee 3 | H50: Auxiliar Enginee 4 | I50: Auxiliar Enginee 5 | J50: Boiler | K50: Description
B51: 46104 | C51: LNG | D51: 45115 | E51: 21142 | F51: 15161 | G51: 16612 | H51: 21762 | I51: 24699 | J51: 4859 | K51: Previous Survey
B52: 46188 | C52: LNG | D52: 72156 | E52: 63995 | F52: 163974 | G52: 82791 | H52: 142963 | I52: 55477 | J52: 127376 | K52: Actual survey
...

Sheet VacuoAr
A1: Density at 15C | B1: FCW Vacuo-Ar
A2: 0.5 | B2: 0.99775
A3: 0.5191 | B3: 0.99775
A4: 0.5192 | B4: 0.99785
A5: 0.5421 | B5: 0.99785
A6: 0.5422 | B6: 0.99795
A7: 0.5673 | B7: 0.99795
A8: 0.5674 | B8: 0.99805
A9: 0.595 | B9: 0.99805
A10: 0.5951 | B10: 0.99815
A11: 0.6255 | B11: 0.99815
A12: 0.6256 | B12: 0.99825
A13: 0.6593 | B13: 0.99825
... A29: 1.1 | B29: 0.99905
